<mujoco model="MovableSittingField">
  <compiler angle="radian" autolimits="true"/>
  <option noslip_iterations="50" noslip_tolerance="1e-10"/>

  <worldbody>
    <body name="block">
      <joint name="pitch" axis="0 1 0" range="-1.0 1.0" stiffness="40.0" damping="120.0" armature="50.0"
             pos="0.2 0 0.73"/>
      <geom type="box" rgba="0.3 0.5 0.2 1"
            condim="3" group="1" density="0"
            size="0.05 0.25 0.01" mass="10.0"
            pos="0.2 0 0.73"
            />
    </body>
  </worldbody>
</mujoco>
